2019-03-13 10:49:26,458 TestMail126AddContacts.py[line:32] INFO 126邮箱添加联系人数据驱动测试开始...
2019-03-13 10:49:43,448 TestMail126AddContacts.py[line:46] INFO 启动服务器,访问126邮箱主页
2019-03-13 10:50:08,138 TestMail126AddContacts.py[line:114] DEBUG 异常信息: Traceback (most recent call last):
  File "C:\Users\Administrator\Desktop\DataDrivenFrameWork\testScripts\TestMail126AddContacts.py", line 51, in test126MailAddContacts
    assert u"收信" in driver.page_source
AssertionError

During handling of the above exception, another exception occurred:

Traceback (most recent call last):
  File "C:\Users\Administrator\Desktop\DataDrivenFrameWork\testScripts\TestMail126AddContacts.py", line 56, in test126MailAddContacts
    u"异常信息: %s" %(username, str(traceback.print_exc())))
TypeError: not all arguments converted during string formatting

2019-03-13 10:52:36,333 TestMail126AddContacts.py[line:32] INFO 126邮箱添加联系人数据驱动测试开始...
2019-03-13 10:52:48,475 TestMail126AddContacts.py[line:46] INFO 启动服务器,访问126邮箱主页
2019-03-13 10:53:03,553 TestMail126AddContacts.py[line:53] INFO 用户ouyang8603登陆后，断言页面关键字收 信成功
2019-03-13 10:53:46,683 TestMail126AddContacts.py[line:114] DEBUG 异常信息: Traceback (most recent call last):
  File "C:\Users\Administrator\Desktop\DataDrivenFrameWork\testScripts\TestMail126AddContacts.py", line 79, in test126MailAddContacts
    contactPersonComment)
  File "C:\Users\Administrator\Desktop\DataDrivenFrameWork\appModules\AddContactPersonAction.py", line 35, in add
    raise e
  File "C:\Users\Administrator\Desktop\DataDrivenFrameWork\appModules\AddContactPersonAction.py", line 27, in add
    apb.starContacts().click()
  File "C:\Users\Administrator\Desktop\DataDrivenFrameWork\pageObjects\AddressBookPage.py", line 48, in starContacts
    raise e
  File "C:\Users\Administrator\Desktop\DataDrivenFrameWork\pageObjects\AddressBookPage.py", line 45, in starContacts
    elementObj = getElement(self.driver, locateType, locatorExpression)
  File "C:\Users\Administrator\Desktop\DataDrivenFrameWork\util\ObjectMap.py", line 12, in getElement
    raise e
  File "C:\Users\Administrator\Desktop\DataDrivenFrameWork\util\ObjectMap.py", line 9, in getElement
    (lambda x: x.find_element(by = locateType, value = locatorExpression))
  File "C:\Users\Administrator\AppData\Local\Programs\Python\Python37\lib\site-packages\selenium\webdriver\support\wait.py", line 80, in until
    raise TimeoutException(message, screen, stacktrace)
selenium.common.exceptions.TimeoutException: Message: 


